<?xml version="1.0" ?>
<!-- =================================================================================== -->
<!-- |    This document was autogenerated by xacro from ur.urdf.xacro                  | -->
<!-- |    EDITING THIS FILE BY HAND IS NOT RECOMMENDED                                 | -->
<!-- =================================================================================== -->
<robot name="ur5">

  <!-- Add URDF transmission elements (for ros_control) -->
  <!--<xacro:ur_arm_transmission prefix="${prefix}" hw_interface="${transmission_hw_interface}" />-->
  <!-- Placeholder for ros2_control transmission which don't yet exist -->
  <!-- links -  main serial chain -->
  <link name="world"/>
  <link name="base_link"/>
  <link name="base_link_inertia">
    <visual>
      <origin rpy="0 0 3.141592653589793" xyz="0 0 0"/>
      <geometry>
        <mesh filename="package://moveit_resources_ur5_description/meshes/visual/base.dae"/>
      </geometry>
    </visual>
    <collision>
      <origin rpy="0 0 3.141592653589793" xyz="0 0 0"/>
      <geometry>
        <mesh filename="package://moveit_resources_ur5_description/meshes/collision/base.stl"/>
      </geometry>
    </collision>
    <inertial>
      <mass value="4.0"/>
      <origin rpy="0 0 0" xyz="0 0 0"/>
      <inertia ixx="0.00443333156" ixy="0.0" ixz="0.0" iyy="0.00443333156" iyz="0.0" izz="0.0072"/>
    </inertial>
  </link>
  <link name="shoulder_link">
    <visual>
      <origin rpy="0 0 3.141592653589793" xyz="0 0 0"/>
      <geometry>
        <mesh filename="package://moveit_resources_ur5_description/meshes/visual/shoulder.dae"/>
      </geometry>
    </visual>
    <collision>
      <origin rpy="0 0 3.141592653589793" xyz="0 0 0"/>
      <geometry>
        <mesh filename="package://moveit_resources_ur5_description/meshes/collision/shoulder.stl"/>
      </geometry>
    </collision>
    <inertial>
      <mass value="3.7"/>
      <origin rpy="0 0 0" xyz="0 0 0"/>
      <inertia ixx="0.014972352344389999" ixy="0.0" ixz="0.0" iyy="0.014972352344389999" iyz="0.0" izz="0.01040625"/>
    </inertial>
  </link>
  <link name="upper_arm_link">
    <visual>
      <origin rpy="1.5707963267948966 0 -1.5707963267948966" xyz="0 0 0.13585"/>
      <geometry>
        <mesh filename="package://moveit_resources_ur5_description/meshes/visual/upperarm.dae"/>
      </geometry>
    </visual>
    <collision>
      <origin rpy="1.5707963267948966 0 -1.5707963267948966" xyz="0 0 0.13585"/>
      <geometry>
        <mesh filename="package://moveit_resources_ur5_description/meshes/collision/upperarm.stl"/>
      </geometry>
    </collision>
    <inertial>
      <mass value="8.393"/>
      <origin rpy="0 1.5707963267948966 0" xyz="-0.2125 0.0 0.136"/>
      <inertia ixx="0.1338857818623325" ixy="0.0" ixz="0.0" iyy="0.1338857818623325" iyz="0.0" izz="0.0151074"/>
    </inertial>
  </link>
  <link name="forearm_link">
    <visual>
      <origin rpy="1.5707963267948966 0 -1.5707963267948966" xyz="0 0 0.0165"/>
      <geometry>
        <mesh filename="package://moveit_resources_ur5_description/meshes/visual/forearm.dae"/>
      </geometry>
    </visual>
    <collision>
      <origin rpy="1.5707963267948966 0 -1.5707963267948966" xyz="0 0 0.0165"/>
      <geometry>
        <mesh filename="package://moveit_resources_ur5_description/meshes/collision/forearm.stl"/>
      </geometry>
    </collision>
    <inertial>
      <mass value="2.275"/>
      <origin rpy="0 1.5707963267948966 0" xyz="-0.196125 0.0 0.0165"/>
      <inertia ixx="0.03121679102890359" ixy="0.0" ixz="0.0" iyy="0.03121679102890359" iyz="0.0" izz="0.004095"/>
    </inertial>
  </link>
  <link name="wrist_1_link">
    <visual>
      <origin rpy="1.5707963267948966 0 0" xyz="0 0 -0.093"/>
      <geometry>
        <mesh filename="package://moveit_resources_ur5_description/meshes/visual/wrist1.dae"/>
      </geometry>
    </visual>
    <collision>
      <origin rpy="1.5707963267948966 0 0" xyz="0 0 -0.093"/>
      <geometry>
        <mesh filename="package://moveit_resources_ur5_description/meshes/collision/wrist1.stl"/>
      </geometry>
    </collision>
    <inertial>
      <mass value="1.219"/>
      <origin rpy="0 0 0" xyz="0 0 0"/>
      <inertia ixx="0.0020138887777775" ixy="0.0" ixz="0.0" iyy="0.0020138887777775" iyz="0.0" izz="0.0021942"/>
    </inertial>
  </link>
  <link name="wrist_2_link">
    <visual>
      <origin rpy="0 0 0" xyz="0 0 -0.095"/>
      <geometry>
        <mesh filename="package://moveit_resources_ur5_description/meshes/visual/wrist2.dae"/>
      </geometry>
    </visual>
    <collision>
      <origin rpy="0 0 0" xyz="0 0 -0.095"/>
      <geometry>
        <mesh filename="package://moveit_resources_ur5_description/meshes/collision/wrist2.stl"/>
      </geometry>
    </collision>
    <inertial>
      <mass value="1.219"/>
      <origin rpy="0 0 0" xyz="0 0 0"/>
      <inertia ixx="0.0018310388509175" ixy="0.0" ixz="0.0" iyy="0.0018310388509175" iyz="0.0" izz="0.0021942"/>
    </inertial>
  </link>
  <link name="wrist_3_link">
    <visual>
      <origin rpy="1.5707963267948966 0 0" xyz="0 0 -0.0818"/>
      <geometry>
        <mesh filename="package://moveit_resources_ur5_description/meshes/visual/wrist3.dae"/>
      </geometry>
    </visual>
    <collision>
      <origin rpy="1.5707963267948966 0 0" xyz="0 0 -0.0818"/>
      <geometry>
        <mesh filename="package://moveit_resources_ur5_description/meshes/collision/wrist3.stl"/>
      </geometry>
    </collision>
    <inertial>
      <mass value="0.1879"/>
      <origin rpy="0 0 0" xyz="0.0 0.0 -0.01525"/>
      <inertia ixx="8.062472608343e-05" ixy="0.0" ixz="0.0" iyy="8.062472608343e-05" iyz="0.0" izz="0.0001321171875"/>
    </inertial>
  </link>
  <!-- base_joint fixes base_link to the environment -->
  <joint name="base_joint" type="fixed">
    <origin rpy="0 0 0" xyz="0 0 0"/>
    <parent link="world"/>
    <child link="base_link"/>
  </joint>
  <!-- joints - main serial chain -->
  <joint name="base_link-base_link_inertia" type="fixed">
    <parent link="base_link"/>
    <child link="base_link_inertia"/>
    <!-- 'base_link' is REP-103 aligned (so X+ forward), while the internal
           frames of the robot/controller have X+ pointing backwards.
           Use the joint between 'base_link' and 'base_link_inertia' (a dummy
           link/frame) to introduce the necessary rotation over Z (of pi rad).
      -->
    <origin rpy="0 0 3.141592653589793" xyz="0 0 0"/>
  </joint>
  <joint name="shoulder_pan_joint" type="revolute">
    <parent link="base_link_inertia"/>
    <child link="shoulder_link"/>
    <origin rpy="0 0 0" xyz="0 0 0.089159"/>
    <axis xyz="0 0 1"/>
    <limit effort="150.0" lower="-6.283185307179586" upper="6.283185307179586" velocity="3.141592653589793"/>
    <dynamics damping="0" friction="0"/>
  </joint>
  <joint name="shoulder_lift_joint" type="revolute">
    <parent link="shoulder_link"/>
    <child link="upper_arm_link"/>
    <origin rpy="1.570796327 0 0" xyz="0 0 0"/>
    <axis xyz="0 0 1"/>
    <limit effort="150.0" lower="-6.283185307179586" upper="6.283185307179586" velocity="3.141592653589793"/>
    <dynamics damping="0" friction="0"/>
  </joint>
  <joint name="elbow_joint" type="revolute">
    <parent link="upper_arm_link"/>
    <child link="forearm_link"/>
    <origin rpy="0 0 0" xyz="-0.425 0 0"/>
    <axis xyz="0 0 1"/>
    <limit effort="150.0" lower="-3.141592653589793" upper="3.141592653589793" velocity="3.141592653589793"/>
    <dynamics damping="0" friction="0"/>
  </joint>
  <joint name="wrist_1_joint" type="revolute">
    <parent link="forearm_link"/>
    <child link="wrist_1_link"/>
    <origin rpy="0 0 0" xyz="-0.39225 0 0.10915"/>
    <axis xyz="0 0 1"/>
    <limit effort="28.0" lower="-6.283185307179586" upper="6.283185307179586" velocity="3.141592653589793"/>
    <dynamics damping="0" friction="0"/>
  </joint>
  <joint name="wrist_2_joint" type="revolute">
    <parent link="wrist_1_link"/>
    <child link="wrist_2_link"/>
    <origin rpy="1.570796327 0 0" xyz="0 -0.09465 -1.941303950897609e-11"/>
    <axis xyz="0 0 1"/>
    <limit effort="28.0" lower="-6.283185307179586" upper="6.283185307179586" velocity="3.141592653589793"/>
    <dynamics damping="0" friction="0"/>
  </joint>
  <joint name="wrist_3_joint" type="revolute">
    <parent link="wrist_2_link"/>
    <child link="wrist_3_link"/>
    <origin rpy="1.570796326589793 3.141592653589793 3.141592653589793" xyz="0 0.0823 -1.688001216681175e-11"/>
    <axis xyz="0 0 1"/>
    <limit effort="28.0" lower="-6.283185307179586" upper="6.283185307179586" velocity="3.141592653589793"/>
    <dynamics damping="0" friction="0"/>
  </joint>
  <!-- <link name="ft_frame"/>
  <joint name="wrist_3_link-ft_frame" type="fixed">
    <parent link="wrist_3_link"/>
    <child link="ft_frame"/>
    <origin rpy="3.141592653589793 0 0" xyz="0 0 0"/>
  </joint> -->
  <!-- ROS-Industrial 'base' frame - base_link to UR 'Base' Coordinates transform -->
  <!-- <link name="base"/>
  <joint name="base_link-base_fixed_joint" type="fixed"> -->
    <!-- Note the rotation over Z of pi radians - as base_link is REP-103
           aligned (i.e., has X+ forward, Y+ left and Z+ up), this is needed
           to correctly align 'base' with the 'Base' coordinate system of
           the UR controller.
      -->
    <!-- <origin rpy="0 0 3.141592653589793" xyz="0 0 0"/>
    <parent link="base_link"/>
    <child link="base"/>
  </joint> -->
  <!-- ROS-Industrial 'flange' frame - attachment point for EEF models -->
  <link name="flange"/>
  <joint name="wrist_3-flange" type="fixed">
    <parent link="wrist_3_link"/>
    <child link="flange"/>
    <origin rpy="0 -1.5707963267948966 -1.5707963267948966" xyz="0 0 0"/>
  </joint>
  <!-- ROS-Industrial 'tool0' frame - all-zeros tool frame -->
  <link name="tool0"/>
  <joint name="flange-tool0" type="fixed">
    <!-- default toolframe - X+ left, Y+ up, Z+ front -->
    <origin rpy="1.5707963267948966 0 1.5707963267948966" xyz="0 0 0"/>
    <parent link="flange"/>
    <child link="tool0"/>
  </joint>
  
  <!--onrobot gripper-->
    <link name="onrobot_rg2_base_link">
    <inertial>
      <origin rpy="0 0 0" xyz="0.0 0.0 0.0"/>
      <mass value="0.7"/>
      <inertia ixx="1.0E-03" ixy="1.0E-06" ixz="1.0E-06" iyy="1.0E-03" iyz="1.0E-06" izz="1.0E-03"/>
    </inertial>
    <visual>
      <origin rpy="0 0 0" xyz="0 0 0"/>
      <geometry>
        <mesh filename="package://moveit_resources_ur5_description/meshes/visual/base_link.stl"/>
      </geometry>
      <material name="">
        <color rgba="0.8 0.8 0.8 1"/>
      </material>
    </visual>
    <collision>
      <origin rpy="0 0 0" xyz="0 0 0"/>
      <geometry>
        <mesh filename="package://moveit_resources_ur5_description/meshes/collision/base_link.stl"/>
      </geometry>
    </collision>
  </link>
  <joint name="joint0" type="fixed">
    <parent link="tool0"/>
    <child link="onrobot_rg2_base_link"/>
    <origin rpy="0. 0. 0." xyz="0. 0. 0."/>
  </joint>

  <link name="left_outer_knuckle">
    <inertial>
      <origin rpy="0 0 0" xyz="0.0 0.0 0.0"/>
      <mass value="0.05"/>
      <inertia ixx="1.0E-03" ixy="1.0E-06" ixz="1.0E-06" iyy="1.0E-03" iyz="1.0E-06" izz="1.0E-03"/>
    </inertial>
    <visual>
      <origin rpy="0 0 0" xyz="0 0 0"/>
      <geometry>
        <mesh filename="package://moveit_resources_ur5_description/meshes/visual/outer_knuckle.stl"/>
      </geometry>
      <material name="">
        <color rgba="0.8 0.8 0.8 1"/>
      </material>
    </visual>
    <collision>
      <origin rpy="0 0 0" xyz="0 0 0"/>
      <geometry>
        <mesh filename="package://moveit_resources_ur5_description/meshes/collision/outer_knuckle.stl"/>
      </geometry>
    </collision>
  </link>

  <link name="left_inner_knuckle">
    <inertial>
      <origin rpy="0 0 0" xyz="0.0 0.0 0.0"/>
      <mass value="0.05"/>
      <inertia ixx="1.0E-03" ixy="1.0E-06" ixz="1.0E-06" iyy="1.0E-03" iyz="1.0E-06" izz="1.0E-03"/>
    </inertial>
    <visual>
      <origin rpy="0 0 0" xyz="0 0 0"/>
      <geometry>
        <mesh filename="package://moveit_resources_ur5_description/meshes/visual/inner_knuckle.stl"/>
      </geometry>
      <material name="">
        <color rgba="0.8 0.8 0.8 1"/>
      </material>
    </visual>
    <collision>
      <origin rpy="0 0 0" xyz="0 0 0"/>
      <geometry>
        <mesh filename="package://moveit_resources_ur5_description/meshes/collision/inner_knuckle.stl"/>
      </geometry>
    </collision>
  </link>

  <link name="left_inner_finger">
    <inertial>
      <origin rpy="0 0 0" xyz="0.0 0.0 0.0"/>
      <mass value="0.05"/>
      <inertia ixx="1.0E-03" ixy="1.0E-06" ixz="1.0E-06" iyy="1.0E-03" iyz="1.0E-06" izz="1.0E-03"/>
    </inertial>
    <visual>
      <origin rpy="0 0 0" xyz="0 0 0"/>
      <geometry>
        <mesh filename="package://moveit_resources_ur5_description/meshes/visual/inner_finger.stl"/>
      </geometry>
      <material name="">
        <color rgba="0.1 0.1 0.1 1"/>
      </material>
    </visual>
    <collision>
      <origin rpy="0 0 0" xyz="0 0 0"/>
      <geometry>
        <mesh filename="package://moveit_resources_ur5_description/meshes/collision/inner_finger.stl"/>
      </geometry>
    </collision>
  </link>
  <link name="right_outer_knuckle">
    <inertial>
      <origin rpy="0 0 0" xyz="0.0 0.0 0.0"/>
      <mass value="0.05"/>
      <inertia ixx="1.0E-03" ixy="1.0E-06" ixz="1.0E-06" iyy="1.0E-03" iyz="1.0E-06" izz="1.0E-03"/>
    </inertial>
    <visual>
      <origin rpy="0 0 0" xyz="0 0 0"/>
      <geometry>
        <mesh filename="package://moveit_resources_ur5_description/meshes/visual/outer_knuckle.stl"/>
      </geometry>
      <material name="">
        <color rgba="0.8 0.8 0.8 1"/>
      </material>
    </visual>
    <collision>
      <origin rpy="0 0 0" xyz="0 0 0"/>
      <geometry>
        <mesh filename="package://moveit_resources_ur5_description/meshes/collision/outer_knuckle.stl"/>
      </geometry>
    </collision>
  </link>

  <link name="right_inner_knuckle">
    <inertial>
      <origin rpy="0 0 0" xyz="0.0 0.0 0.0"/>
      <mass value="0.05"/>
      <inertia ixx="1.0E-03" ixy="1.0E-06" ixz="1.0E-06" iyy="1.0E-03" iyz="1.0E-06" izz="1.0E-03"/>
    </inertial>
    <visual>
      <origin rpy="0 0 0" xyz="0 0 0"/>
      <geometry>
        <mesh filename="package://moveit_resources_ur5_description/meshes/visual/inner_knuckle.stl"/>
      </geometry>
      <material name="">
        <color rgba="0.8 0.8 0.8 1"/>
      </material>
    </visual>
    <collision>
      <origin rpy="0 0 0" xyz="0 0 0"/>
      <geometry>
        <mesh filename="package://moveit_resources_ur5_description/meshes/collision/inner_knuckle.stl"/>
      </geometry>
    </collision>
  </link>

  <link name="right_inner_finger">
    <inertial>
      <origin rpy="0 0 0" xyz="0.0 0.0 0.0"/>
      <mass value="0.05"/>
      <inertia ixx="1.0E-03" ixy="1.0E-06" ixz="1.0E-06" iyy="1.0E-03" iyz="1.0E-06" izz="1.0E-03"/>
    </inertial>
    <visual>
      <origin rpy="0 0 0" xyz="0 0 0"/>
      <geometry>
        <mesh filename="package://moveit_resources_ur5_description/meshes/visual/inner_finger.stl"/>
      </geometry>
      <material name="">
        <color rgba="0.1 0.1 0.1 1"/>
      </material>
    </visual>
    <collision>
      <origin rpy="0 0 0" xyz="0 0 0"/>
      <geometry>
        <mesh filename="package://moveit_resources_ur5_description/meshes/collision/inner_finger.stl"/>
      </geometry>
    </collision>
  </link>

  <joint name="finger_joint" type="revolute">
    <origin rpy="0 0 0" xyz="0 -0.017178 0.125797"/>
    <parent link="onrobot_rg2_base_link"/>
    <child link="left_outer_knuckle"/>
    <axis xyz="-1 0 0"/>
    <limit effort="1000" lower="-0.558505" upper="0.785398" velocity="100.0"/>
  </joint>
  <joint name="left_inner_knuckle_joint" type="revolute">
    <origin rpy="0 0 0.0" xyz="0 -0.007678 0.1422970"/>
    <parent link="onrobot_rg2_base_link"/>
    <child link="left_inner_knuckle"/>
    <axis xyz="1 0 0"/>
    <limit effort="1000" lower="-0.785398" upper="0.785398" velocity="100.0"/>
    <mimic joint="finger_joint" multiplier="-1" offset="0"/>
  </joint>
  <joint name="left_inner_finger_joint" type="revolute">
    <origin rpy="0 0 0" xyz="0 -0.039592 0.038177000000000016"/>
    <parent link="left_outer_knuckle"/>
    <child link="left_inner_finger"/>
    <axis xyz="1 0 0"/>
    <limit effort="1000" lower="-0.872665" upper="0.872665" velocity="100.0"/>
    <mimic joint="finger_joint" multiplier="1" offset="0"/>
  </joint>
  <joint name="right_outer_knuckle_joint" type="revolute">
    <origin rpy="0 0 3.141592653589793" xyz="0 0.017178 0.125797"/>
    <parent link="onrobot_rg2_base_link"/>
    <child link="right_outer_knuckle"/>
    <axis xyz="1 0 0"/>
    <limit effort="1000" lower="-0.785398" upper="0.785398" velocity="100.0"/>
    <mimic joint="finger_joint" multiplier="-1" offset="0"/>
  </joint>
  <joint name="right_inner_knuckle_joint" type="revolute">
    <origin rpy="0 0 -3.141592653589793" xyz="0 0.007678 0.1422970"/>
    <parent link="onrobot_rg2_base_link"/>
    <child link="right_inner_knuckle"/>
    <axis xyz="1 0 0"/>
    <limit effort="1000" lower="-0.785398" upper="0.785398" velocity="100.0"/>
    <mimic joint="finger_joint" multiplier="-1" offset="0"/>
  </joint>
  <joint name="right_inner_finger_joint" type="revolute">
    <origin rpy="0 0 0" xyz="0 -0.039592 0.038177000000000016"/>
    <parent link="right_outer_knuckle"/>
    <child link="right_inner_finger"/>
    <axis xyz="1 0 0"/>
    <limit effort="1000" lower="-0.872665" upper="0.872665" velocity="100.0"/>
    <mimic joint="finger_joint" multiplier="1" offset="0"/>
  </joint>
</robot>
