<?xml version="1.0" ?>
<!-- =================================================================================== -->
<!-- |    This document was autogenerated by xacro from manipulator.xacro              | -->
<!-- |    EDITING THIS FILE BY HAND IS NOT RECOMMENDED                                 | -->
<!-- =================================================================================== -->
<robot name="manipulator_2">

  <link name="world"/>
  <joint name="world_joint" type="fixed">
    <parent link="world"/>
    <child link="base_link"/>
    <origin rpy="0.0 0.0 0.0" xyz="0.0 0.0 1.0"/>
  </joint>

  <material name="orange">
    <color rgba="1 0.8 0.1 1"/>
  </material>

  <!-- Base Link -->
  <link name="base_link">
    <collision>
      <origin rpy="0 -1.5707963267948966 0" xyz="0 0 0"/>
      <geometry>
        <mesh filename="package://moveit_resources_manipulator_2_description/meshes/original/base_link.stl"/>
      </geometry>
    </collision>
    <visual>
      <origin rpy="0 -1.5707963267948966 0" xyz="0 0 0"/>
      <geometry>
        <mesh filename="package://moveit_resources_manipulator_2_description/meshes/original/base_link.stl"/>
      </geometry>
      <material name="orange"/>
    </visual>
    <inertial>
      <origin rpy="0 -1.57 0" xyz="0 0 0.4"/>
      <mass value="5.7"/>
      <inertia ixx="0.13" ixy="0.0" ixz="0" iyy="0.012" iyz="0.0" izz="0.12"/>
    </inertial>
  </link>
  <!-- joint1 -->
  <joint name="j1" type="revolute">
    <parent link="base_link"/>
    <child link="l1"/>
    <origin rpy="0 -1.5707963267948966 0" xyz="0 0 0"/>
    <axis xyz="1 0 0"/>
    <limit effort="3000" lower="-0.47123889803846897" upper="0.6911503837897545" velocity="1.0"/>
    <dynamics damping="0.5" friction="120"/>
  </joint>

  <!-- camera_joint -->
  <joint name="jc" type="fixed">
    <parent link="base_link"/>
    <child link="camera"/>
    <origin rpy="-1.5707963267948966 0 -1.5707963267948966" xyz="0.0 0.3 -0.1"/>
  </joint>

  <!-- link_camera -->
  <link name="camera">
    <collision>
      <origin rpy="0 0 0" xyz="0 0 0"/>
      <geometry>
        <mesh filename="package://moveit_resources_manipulator_2_description/meshes/original/L515.stl"/>
      </geometry>
    </collision>
    <visual>
      <origin rpy="0 0 0" xyz="0 0 0"/>
      <geometry>
        <mesh filename="package://moveit_resources_manipulator_2_description/meshes/original/L515.stl"/>
      </geometry>
      <material name="orange"/>
    </visual>
  </link>

  <!-- link1 -->
  <link name="l1">
    <collision>
      <origin rpy="0 0 0" xyz="0 0 0"/>
      <geometry>
        <mesh filename="package://moveit_resources_manipulator_2_description/meshes/original/l1.stl"/>
      </geometry>
    </collision>
    <visual>
      <origin rpy="0 0 0" xyz="0 0 0"/>
      <geometry>
        <mesh filename="package://moveit_resources_manipulator_2_description/meshes/original/l1.stl"/>
      </geometry>
      <material name="orange"/>
    </visual>
    <inertial>
      <origin rpy="0 0 0" xyz="0 0 0"/>
      <mass value="1.2778"/>
      <inertia ixx="0.0046902" ixy="0" ixz="-0.0" iyy="0.0047235" iyz="0.0" izz="0.00020263"/>
    </inertial>
  </link>
  <!-- joint2 -->
  <joint name="j2" type="revolute">
    <parent link="l1"/>
    <child link="l2"/>
    <origin rpy="1.5707963267948966 1.5707963267948966 0" xyz="0 0.032 -0.1273"/>
    <axis xyz="0 0 1"/>
    <limit effort="3000" lower="-0.17435839227423353" upper="1.1341149479459154" velocity="1.0"/>
    <dynamics damping="0.5" friction="80"/>
  </joint>

  <!-- link2 -->
  <link name="l2">
    <collision>
      <origin rpy="0 0 0" xyz="0 0 0"/>
      <geometry>
        <mesh filename="package://moveit_resources_manipulator_2_description/meshes/original/l2.stl"/>
      </geometry>
    </collision>
    <visual>
      <origin rpy="0 0 0" xyz="0 0 0"/>
      <geometry>
        <mesh filename="package://moveit_resources_manipulator_2_description/meshes/original/l2.stl"/>
      </geometry>
      <material name="orange"/>
    </visual>
    <inertial>
      <origin rpy="0 0 0" xyz="0.24332 -0.038385 0"/>
      <mass value="2.7848"/>
      <inertia ixx="0.0088113" ixy="0.0" ixz="0.0" iyy="0.037743" iyz="-0.0" izz="0.034608"/>
    </inertial>
  </link>
  <!-- joint3 -->
  <joint name="j3" type="revolute">
    <parent link="l2"/>
    <child link="l3"/>
    <origin rpy="0 0 0" xyz="0.5116 -0.025 0"/>
    <axis xyz="0 0 1"/>
    <limit effort="3000" lower="-0.7319910882864218" upper="0.3675663404700058" velocity="1.0"/>
    <dynamics damping="0.5" friction="80"/>
  </joint>

  <!-- link3 -->
  <link name="l3">
    <collision>
      <origin rpy="0 0 0" xyz="0 0 0"/>
      <geometry>
        <mesh filename="package://moveit_resources_manipulator_2_description/meshes/original/l3.stl"/>
      </geometry>
    </collision>
    <visual>
      <origin rpy="0 0 0" xyz="0 0 0"/>
      <geometry>
        <mesh filename="package://moveit_resources_manipulator_2_description/meshes/original/l3.stl"/>
      </geometry>
      <material name="orange"/>
    </visual>
    <inertial>
      <origin rpy="0 0 0" xyz="0.062429 0.0032856 -0.00043376"/>
      <mass value="1.1648"/>
      <inertia ixx="0.00039119" ixy="0.0" ixz="0.0" iyy="0.00026141" iyz="0.0" izz="0.000603"/>
    </inertial>
  </link>
  
  <!-- joint4 -->
  <joint name="j4" type="revolute">
    <parent link="l3"/>
    <child link="l4"/>
    <origin rpy="-1.5707963267948966 3.14 0" xyz="0.161 0 0"/>
    <axis xyz="0 0 -1"/>
    <limit effort="3000" lower="-2.0074777056438777" upper="1.0995574287564276" velocity="1.0"/>
    <dynamics damping="0.5" friction="80"/>
  </joint>

  <!-- link4 -->
  <link name="l4">
    <collision>
      <origin rpy="0 0 0" xyz="0 0 0"/>
      <geometry>
        <mesh filename="package://moveit_resources_manipulator_2_description/meshes/original/l4.stl"/>
      </geometry>
    </collision>
    <visual>
      <origin rpy="0 0 0" xyz="0 0 0"/>
      <geometry>
        <mesh filename="package://moveit_resources_manipulator_2_description/meshes/original/l4.stl"/>
      </geometry>
      <material name="orange"/>
    </visual>
    <inertial>
      <origin rpy="0 0 0" xyz="-0.018965 -0.0039484 -0.10219"/>
      <mass value="2.2356"/>
      <inertia ixx="0.005307" ixy="-0.0" ixz="0.0" iyy="0.0050788" iyz="0.0" izz="0.0011551"/>
    </inertial>
  </link>
  <!-- joint5 -->
  <joint name="j5" type="revolute">
    <parent link="l4"/>
    <child link="l5"/>
    <origin rpy="1.5707963267948966 0 0" xyz="-0.04445 0 -0.212"/>
    <axis xyz="0 0 1"/>
    <limit effort="3000" lower="-1.413716694115407" upper="-0.06911503837897544" velocity="1.0"/>
    <dynamics damping="0.5" friction="80"/>
  </joint>

  <!-- link5 -->
  <link name="l5">
    <collision>
      <origin rpy="0 0 0" xyz="0 0 0"/>
      <geometry>
        <mesh filename="package://moveit_resources_manipulator_2_description/meshes/original/l5.stl"/>
      </geometry>
    </collision>
    <visual>
      <origin rpy="0 0 0" xyz="0 0 0"/>
      <geometry>
        <mesh filename="package://moveit_resources_manipulator_2_description/meshes/original/l5.stl"/>
      </geometry>
      <material name="orange"/>
    </visual>
    <inertial>
      <origin rpy="0 0 0" xyz="0.033318 -0.13193 -9.0087E-05"/>
      <mass value="1.8032"/>
      <inertia ixx="0.0078726" ixy="0" ixz="0" iyy="0.0002976" iyz="0" izz="0.0081459"/>
    </inertial>
  </link>
  <!-- joint6 -->
  <joint name="j6" type="continuous">
    <parent link="l5"/>
    <child link="l6"/>
    <origin rpy="-1.5707963267948966 0 0" xyz="0.01846 -0.336 0"/>
    <axis xyz="0 0 1"/>
    <dynamics damping="0.5" friction="80"/>
  </joint>

  <!-- link6 -->
  <link name="l6">
    <collision>
      <origin rpy="0 0 0" xyz="0 0 0"/>
      <geometry>
        <box size="0.001 0.001 0.001"/>
      </geometry>
    </collision>
    <visual>
      <origin rpy="0 0 0" xyz="0 0 0"/>
      <geometry>
        <box size="0.001 0.001 0.001"/>
      </geometry>
      <material name="orange"/>
    </visual>
    <inertial>
      <origin rpy="0 0 0" xyz="0.0083277 -0.0005493 -0.0059114"/>
      <mass value="0.2092"/>
      <inertia ixx="0.1" ixy="0.0" ixz="0.0" iyy="0.1" iyz="0.0" izz="0.1"/>
    </inertial>
  </link>

  <link name="hand">
    <inertial>
      <mass value="1"/>
      <origin rpy="0 0 0" xyz="0 0 0"/>
      <inertia ixx="0.5" ixy="0.0" ixz="0.0" iyy="0.5" iyz="0.0" izz="0.5"/>
    </inertial>
    <visual>
      <origin rpy="0 0 0" xyz="0 0 0"/>
      <geometry>
        <mesh filename="package://moveit_resources_manipulator_2_description/meshes/original/gripper.stl"/>
      </geometry>
      <material name="">
        <color rgba="1 1 1 1"/>
      </material>
    </visual>
    <collision>
      <origin rpy="0 0 0" xyz="0 0 0"/>
      <geometry>
        <mesh filename="package://moveit_resources_manipulator_2_description/meshes/original/gripper.stl"/>
      </geometry>
    </collision>
  </link>
  <link name="leftfinger">
    <inertial>
      <mass value="0.5"/>
      <origin rpy="0 0 0" xyz="0 0 0"/>
      <inertia ixx="0.1" ixy="0.0" ixz="0.0" iyy="0.1" iyz="0.0" izz="0.1"/>
    </inertial>
    <visual>
      <origin rpy="0 0 0" xyz="0 0 0"/>
      <geometry>
        <mesh filename="package://moveit_resources_manipulator_2_description/meshes/original/f1.stl"/>
      </geometry>
      <material name="">
        <color rgba="1 1 1 1"/>
      </material>
    </visual>
    <collision>
      <origin rpy="0 0 0" xyz="0 0 0"/>
      <geometry>
        <mesh filename="package://moveit_resources_manipulator_2_description/meshes/original/f1.stl"/>
      </geometry>
    </collision>
  </link>
  <link name="rightfinger">
    <inertial>
      <mass value="0.5"/>
      <origin rpy="0 0 0" xyz="0 0 0"/>
      <inertia ixx="0.1" ixy="0.0" ixz="0.0" iyy="0.1" iyz="0.0" izz="0.1"/>
    </inertial>
    <visual>
      <origin rpy="0 0 0" xyz="0 0 0"/>
      <geometry>
        <mesh filename="package://moveit_resources_manipulator_2_description/meshes/original/f2.stl"/>
      </geometry>
      <material name="">
        <color rgba="1 1 1 1"/>
      </material>
    </visual>
    <collision>
      <origin rpy="0 0 0" xyz="0 0 0"/>
      <geometry>
        <mesh filename="package://moveit_resources_manipulator_2_description/meshes/original/f2.stl"/>
      </geometry>
    </collision>
  </link>
  <joint name="finger_joint1" type="revolute">
    <parent link="hand"/>
    <child link="leftfinger"/>
    <origin rpy="1.5707963267948966 0 3.141592653589793" xyz="0.04 0 0"/>
    <axis xyz="0 0 1"/>
    <limit effort="40" lower="-0.5" upper="0.1" velocity="3"/>
    <dynamics damping="0.9" friction="5"/>
  </joint>

  <joint name="finger_joint2" type="revolute">
    <parent link="hand"/>
    <child link="rightfinger"/>
    <origin rpy="1.5707963267948966 0 0" xyz="-0.04 0 0"/>
    <axis xyz="0 0 1"/>
    <limit effort="40" lower="-0.5" upper="0.1" velocity="3"/>
    <dynamics damping="0.9" friction="5"/>
  </joint>


  <!-- manipulator/gripper joint -->
  <joint name="hand_joint" type="fixed">
    <parent link="l6"/>
    <child link="hand"/>
    <origin rpy="0 0 0" xyz="0 0 0"/>
  </joint>

</robot>
